# 回测ok，模拟交易出现如下问题：

handle_data函数运行失败，今天无法生成信号: handle_data() internal error line 27, in handle_data File "python2.7/site-packages/pandas/core/indexing.py", line 73, in __getitem__ return self._getitem_axis(key, axis=0) File "python2.7/site-packages/pandas/core/indexing.py", line 924, in _getitem_axis return self._get_label(key, axis=axis) File "python2.7/site-packages/pandas/core/indexing.py", line 89, in _get_label return self.obj._xs(label, axis=axis) File "python2.7/site-packages/pandas/core/generic.py", line 1466, in xs loc = self.index.get_loc(key) File "python2.7/site-packages/pandas/tseries/index.py", line 1243, in get_loc return Index.get_loc(self, key, method=method) File "python2.7/site-packages/pandas/core/index.py", line 1437, in get_loc return self._engine.get_loc(_values_from_object(key)) File "index.pyx", line 537, in pandas.index.DatetimeEngine.get_loc (pandas/index.c:10254) File "index.pyx", line 568, in pandas.index.DatetimeEngine.get_loc (pandas