# 为什么回测时没问题,模拟时报错

错误提示：
2016-07-20 09:09 [SYS ERROR] handle_data函数运行失败，今天无法生成信号: handle_data() internal error line 39, in handle_data KeyError: u'002759.XSHE'

相关代码:

def initialize(account):
    
    account.day_counter = {}  #
    account.sell_sign = {}  #
    pass
            
def handle_data(account):
    today = Date.fromDateTime(account.current_date)
    OPEN  = account.get_attribute_history('openPrice',3)
    CLOSE = account.get_attribute_history('closePrice',3)
    HIGH  = account.get_attribute_history('highPrice',3)
    LOW   = account.get_attribute_history('lowPrice',3)
    #VOL   = account.get_attribute_history('Volume',3)
    
    buystock=[]
    for stk in account.valid_secpos :
            account.day_counter[stk] = account.day_counter[stk] + 1
            
     运行到这里出错，请高手解答，万分感谢