# universe=set_universe('ZXB')报错

---------------------------------------------------------------------------
ValueError                                Traceback (most recent call last)
&lt;mercury-input-4-3f667eabf492&gt; in &lt;module&gt;()
     10 end =   '2012-1-15'                         # 回测结束时间
     11 benchmark = 'HS300'                        # 策略参考标准
---&gt; 12 universe = set_universe('ZXB')           # 证券池，支持股票和基金
     13 capital_base = 1000000                   # 起始资金
     14 freq = 'd'                                 # 策略类型，'d'表示日间策略使用日线回测，'m'表示日内策略使用分钟线回测

python2.7/site-packages/quartz/data/universe.pyc in set_universe(symbol, date)
     95         for line in csv.reader(raw):
     96             if line == ['-1:No Data Returned']:
---&gt; 97                 raise ValueError("Please verify universe name or ID!")
     98             elif 'secID' in line:
     99                 pass

ValueError: Please verify universe name or ID!
---------------------------------------------------------------------------
怎么回事。。之前一直是好的。。API变了？？