# 为啥set_universe()不能用了？

set_universe('000906.ZICN')
会报错：ValueError: Please verify universe name or ID!

set_universe('ZZ500')
返回值：['-1:No Data Returned']