# 实盘运行一直报错

2016-08-08 09:11 [SYS ERROR] handle_data函数运行失败，今天无法生成信号: handle_data() internal error line 25, in handle_data File "quartz_live/sim_condition/env.py", line 763, in _get_daily_attribute_history self.fill_daily_data(start, end, keeplen=0) File "quartz_live/sim_condition/env.py", line 656, in fill_daily_data self.data_all[j] = np.concatenate((np.array([[np.nan]*(idx_end-idx_start) for _ in range(7)]), self.data_all[j]), axis=1) ValueError: all the input array dimensions except for the concatenation axis must match exactly