# 为什么handle_data中不能调用log了？

2016-09-28 09:07 [SYS ERROR] handle_data函数运行失败，今天无法生成信号: handle_data() internal error line 189, in handle_data NameError: global name 'log' is not defined