# 什么问题， 刚才可以， 现在不行 。

ConnectionError Traceback (most recent call last) &lt;mercury-input-16-AC575772001C4019A539458B77A5E411&gt; in &lt;module&gt;()
----&gt; 1 DataAPI.EquGet(equTypeCD=u"A",secID=u"",ticker=u"",listStatusCD=u"",field=u"",pandas="1") /home/ipython/anaconda/lib/python2.7/site-packages/DataAPI/DATAYES.pyc in EquGet(equTypeCD, secID, ticker, listStatusCD, field, pandas)
  20233         requestString.append(field)   20234 if split_param is None: &gt; 20235         csvString = api_base.__getCSV__(''.join(requestString), httpClient, gw=False)   20236 if csvString is None or len(csvString) == 0 or (csvString[0] == '-' and csvString[1] != '1') or csvString[0] == '{':   20237 api_base.handle_error(csvString, 106) /home/ipython/anaconda/lib/python2.7/site-packages/DataAPI/api_base.pyc in __getCSV__(requestString, httpClient, gw)
     54         raise Exception('Query timeout, maybe requested data is too large')      55 except Exception, e: ---&gt; 56         raise e      57      58 def get_cache_key(frame): ConnectionError: ('Connection aborted.', BadStatusLine("''",))