# 跑了一个月的策略昨天报异常，帮忙看下

有两个策略，都是一样的报错，请看下

报错：
2017-05-10 07:05 [SYS FATAL] 重启失败:initialize() internal error Traceback (most recent call last): File "build/bdist.linux-x86_64/egg/quartz/account/live_account.py", line 299, in from_code File "build/bdist.linux-x86_64/egg/quartz/data/trading_calendar.py", line 162, in _parse_refresh_rate File "build/bdist.linux-x86_64/egg/quartz/data/trading_calendar.py", line 120, in _parse_daily_refresh_rate File "build/bdist.linux-x86_64/egg/quartz/utils/special_trading_days.py", line 59, in get_handle_days File "build/bdist.linux-x86_64/egg/quartz/utils/special_trading_days.py", line 85, in _get_weekly_handle_days KeyError: datetime.datetime(2017, 8, 11, 0, 0)

2017-05-09 20:48 [SYS FATAL] 重启失败:initialize() internal error Traceback (most recent call last): File "build/bdist.linux-x86_64/egg/quartz/account/live_account.py", line 299, in from_code File "build/bdist.linux-x86_64/egg/quartz/data/trading_calendar.py", line 162, in _parse_refresh_rate File "build/bdist.linux-x86_64/egg/quartz/data/trading_calendar.py", line 120, in _parse_daily_refresh_rate File "build/bdist.linux-x86_64/egg/quartz/utils/special_trading_days.py", line 59, in get_handle_days File "build/bdist.linux-x86_64/egg/quartz/utils/special_trading_days.py", line 85, in _get_weekly_handle_days KeyError: datetime.datetime(2017, 8, 11, 0, 0) 