# quartz.backtest报错，一模一样的参数，昨天还可以运行

---------------------------------------------------------------------------
ValueError                                Traceback (most recent call last)
&lt;mercury-input-4-BE61A6FBFD7740218FDADB65A6CA44E0&gt; in &lt;module&gt;()
    194                 kbnumber[i] = 0
    195     return
--&gt; 196 bt, perf =  quartz.backtest(start = _his['tradeDate'].iloc[-1],end = _his['tradeDate'].iloc[-1],benchmark = benchmark,universe = universe,capital_base = capital_base,initialize = initialize,handle_data = handle_data,refresh_rate = refresh_rate,freq = freq)
    197 cols = []
    198 for i in range(0,len(df)):

ValueError: too many values to unpack