# 分红再投 0.0 份额到账  然后报错

2017-01-18 00:00:00: 基金 100032.OFCN 分红再投 0.0 份额到账
---------------------------------------------------------------------------
RuntimeError                              Traceback (most recent call last)
&lt;mercury-input-21-3B6CEC63A87A42E58C4394D0AD88C071&gt; in &lt;module&gt;()
    166                                             max_history_window=max_history_window, accounts=accounts,
    167                                             preload_data=_QUARTZ_PRELOAD_DATA,
--&gt; 168                                             display=True, return_quartz_data=True)
    169     _QUARTZ_CACHE['start'] = start
    170     _QUARTZ_CACHE['end'] = end

/home/ipython/anaconda/lib/python2.7/site-packages/mercuryq-quartz.egg/quartz/backtest.pyc in backtest(start, end, benchmark, universe, capital_base, initialize, handle_data, commission, slippage, refresh_rate, freq, security_base, security_cost, max_history_window, accounts, *args, **kwargs)

/home/ipython/anaconda/lib/python2.7/site-packages/mercuryq-quartz.egg/quartz/backtest.pyc in backtest_daily(context, backtest_calendar, backtest_data_roller, **kwargs)

/home/ipython/anaconda/lib/python2.7/site-packages/mercuryq-quartz.egg/quartz/context/context.pyc in settlement(self)

/home/ipython/anaconda/lib/python2.7/site-packages/mercuryq-quartz.egg/quartz/broker/otc_fund_broker.pyc in settlement(self, *args, **kwargs)

RuntimeError: dictionary changed size during iteration