# 策略没改，今天会测不了，请教一下大神问题出在哪里？

Exception                                 Traceback (most recent call last)
<mercury-input-5-6F892A8A8FD94EAB8821B8092BBC8D68> in <module>()
     64                                             accounts=accounts, preload_data=_QUARTZ_PRELOAD_DATA,
     65                                             display=True, return_quartz_data=True,
---> 66                                             threaded=quartz_createVar.get('threaded', True), need_tracking=True)
     67     _QUARTZ_CACHE['start'] = start
     68     _QUARTZ_CACHE['end'] = end

/home/ipython/anaconda/lib/python2.7/site-packages/mercuryq-quartz-3.6.0-925.egg/quartz/utils/tracking_utils.pyc in _decorator(*args, **kwargs)

/home/ipython/anaconda/lib/python2.7/site-packages/mercuryq-quartz-3.6.0-925.egg/quartz/backtest.pyc in backtest(start, end, benchmark, universe, capital_base, initialize, handle_data, post_trading_day, commission, slippage, refresh_rate, freq, security_base, security_cost, max_history_window, accounts, threaded, display, preload_data, *args, **kwargs)

/home/ipython/anaconda/lib/python2.7/site-packages/mercuryq-quartz-3.6.0-925.egg/quartz/data/data_portal.pyc in batch_load_data(self, sim_params, disabled_service, **kwargs)

/home/ipython/anaconda/lib/python2.7/site-packages/mercuryq-quartz-3.6.0-925.egg/quartz/universe/universe.pyc in batch_load_data(self, universe, trading_days, benchmark, calendar_service, **kwargs)

/home/ipython/anaconda/lib/python2.7/site-packages/mercuryq-quartz-3.6.0-925.egg/quartz/universe/universe.pyc in get_st_dict_from_cache(univ_set, trading_days)

/home/ipython/anaconda/lib/python2.7/site-packages/mercuryq-quartz-3.6.0-925.egg/quartz/data_loader/cache_api.pyc in get_st_security_from_cache(begin_date, end_date, sec_id, field)

Exception: The data is not available at this moment. Traceback (most recent call last):
  File "build/bdist.linux-x86_64/egg/quartz/data_loader/cache_api.py", line 947, in get_st_security_from_cache
  File "/home/ipython/anaconda/lib/python2.7/site-packages/zerorpc/core.py", line 257, in <lambda>
    return lambda *args, **kargs: self(method, *args, **kargs)
  File "/home/ipython/anaconda/lib/python2.7/site-packages/zerorpc/core.py", line 249, in __call__
    return self._process_response(request_event, bufchan, timeout)
  File "/home/ipython/anaconda/lib/python2.7/site-packages/zerorpc/core.py", line 226, in _process_response
    'calling remote method {0}'.format(request_event.name)))
  File "/home/ipython/anaconda/lib/python2.7/site-packages/zerorpc/core.py", line 220, in raise_error
    raise ex
TimeoutExpired: timeout after 300s, when calling remote method get_sec_st