# 回测时一直出现这个error。。请问怎么回事呀

Traceback (most recent call last):   File "build/bdist.linux-x86_64/egg/quartz/data_loader/cache_api.py", line 170, in MktDailyDataFrameGet   File "/home/ipython/anaconda/lib/python2.7/site-packages/zerorpc/core.py", line 257, in <lambda>     return lambda *args, **kargs: self(method, *args, **kargs)   File "/home/ipython/anaconda/lib/python2.7/site-packages/zerorpc/core.py", line 249, in __call__     return self._process_response(request_event, bufchan, timeout)   File "/home/ipython/anaconda/lib/python2.7/site-packages/zerorpc/core.py", line 226, in _process_response     'calling remote method {0}'.format(request_event.name)))   File "/home/ipython/anaconda/lib/python2.7/site-packages/zerorpc/core.py", line 220, in raise_error     raise ex TimeoutExpired: timeout after 300s, when calling remote method get_daily_data_raw