# 回测失败，提示调用get_directed_one_trading_day超时

用notebook自带的策略模板，点击运行也会产生报错。
感觉是这句：

```python
hist = context.history(symbol=context.get_universe(exclude_halt=True), attribute='PE', time_range=1, style='tas')[previous_date]
```

下面是详细的失败原因：

---------------------------------------------------------------------------
Exception                                 Traceback (most recent call last)
<mercury-input-4-17E78FC741A148E1BDED16D1BAA69A80> in <module>()
     76                                             accounts=accounts, preload_data=_QUARTZ_PRELOAD_DATA,
     77                                             display=True, return_quartz_data=True,
---> 78                                             threaded=quartz_createVar.get('threaded', True), need_tracking=True)
     79     _QUARTZ_CACHE['start'] = start
     80     _QUARTZ_CACHE['end'] = end

/home/ipython/anaconda/lib/python2.7/site-packages/mercuryq-quartz-3.61.0-1281.egg/quartz/utils/tracking_utils.pyc in _decorator(*args, **kwargs)

/home/ipython/anaconda/lib/python2.7/site-packages/mercuryq-quartz-3.61.0-1281.egg/quartz/backtest.pyc in backtest(start, end, benchmark, universe, capital_base, initialize, handle_data, post_trading_day, commission, slippage, refresh_rate, freq, security_base, security_cost, max_history_window, accounts, threaded, display, preload_data, *args, **kwargs)

/home/ipython/anaconda/lib/python2.7/site-packages/mercuryq-quartz-3.61.0-1281.egg/quartz/data/data_portal.pyc in batch_load_data(self, sim_params, disabled_service, **kwargs)

/home/ipython/anaconda/lib/python2.7/site-packages/mercuryq-quartz-3.61.0-1281.egg/quartz/data/market_service.pyc in batch_load_data(self, start, end, universe, calendar_service, universe_service, asset_service, **kwargs)

/home/ipython/anaconda/lib/python2.7/site-packages/mercuryq-quartz-3.61.0-1281.egg/quartz/data/market_service.pyc in rolling_load_daily_data(self, trading_days, max_cache_days)

/home/ipython/anaconda/lib/python2.7/site-packages/mercuryq-quartz-3.61.0-1281.egg/quartz/data/market_service.pyc in rolling_load_daily_data(self, trading_days, max_cache_days, asset_service)

/home/ipython/anaconda/lib/python2.7/site-packages/mercuryq-quartz-3.61.0-1281.egg/quartz/data/market_service.pyc in _load_dividends(self, trading_days)

/home/ipython/anaconda/lib/python2.7/site-packages/mercuryq-quartz-3.61.0-1281.egg/quartz/data/market_service.pyc in _load_dividends(universe, trading_days)

/home/ipython/anaconda/lib/python2.7/site-packages/mercuryq-quartz-3.61.0-1281.egg/quartz/data_loader/market_loader.pyc in load_dividend_data(universe, trading_days, from_cache)

/home/ipython/anaconda/lib/python2.7/site-packages/mercuryq-quartz-3.61.0-1281.egg/quartz/data_loader/cache_api.pyc in load_dividend_data_from_cache(universe, trading_days)

Exception: The data is not available at this moment. Traceback (most recent call last):
  File "build/bdist.linux-x86_64/egg/quartz/data_loader/cache_api.py", line 869, in load_dividend_data_from_cache
  File "/home/ipython/anaconda/lib/python2.7/site-packages/zerorpc/core.py", line 257, in <lambda>
    return lambda *args, **kargs: self(method, *args, **kargs)
  File "/home/ipython/anaconda/lib/python2.7/site-packages/zerorpc/core.py", line 249, in __call__
    return self._process_response(request_event, bufchan, timeout)
  File "/home/ipython/anaconda/lib/python2.7/site-packages/zerorpc/core.py", line 226, in _process_response
    'calling remote method {0}'.format(request_event.name)))
  File "/home/ipython/anaconda/lib/python2.7/site-packages/zerorpc/core.py", line 220, in raise_error
    raise ex
TimeoutExpired: timeout after 300s, when calling remote method load_dividend_data